Usage: streamlit run [OPTIONS] TARGET [ARGS]...
Try 'streamlit run --help' for help.

Error: Invalid value: File does not exist: dashboard.py

      ðŸ‘‹ Welcome to Streamlit!

      If you'd like to receive helpful onboarding emails, news, offers, promotions,
      and the occasional swag, please enter your email address below. Otherwise,
      leave this field blank.

      Email:  
  You can now view your Streamlit app in your browser.

  Local URL: http://localhost:8080
  Network URL: http://171.64.52.112:8080
  External URL: http://171.64.52.112:8080


  You can now view your Streamlit app in your browser.

  Local URL: http://localhost:8080
  Network URL: http://171.64.52.112:8080
  External URL: http://171.64.52.112:8080

2025-06-29 20:18:58.860 Uncaught app execution
Traceback (most recent call last):
  File "/home/tristan8/stanford_redcap/venv/lib/python3.10/site-packages/pandas/core/indexes/base.py", line 3812, in get_loc
    return self._engine.get_loc(casted_key)
  File "pandas/_libs/index.pyx", line 167, in pandas._libs.index.IndexEngine.get_loc
  File "pandas/_libs/index.pyx", line 196, in pandas._libs.index.IndexEngine.get_loc
  File "pandas/_libs/hashtable_class_helper.pxi", line 7088, in pandas._libs.hashtable.PyObjectHashTable.get_item
  File "pandas/_libs/hashtable_class_helper.pxi", line 7096, in pandas._libs.hashtable.PyObjectHashTable.get_item
KeyError: 'is_eligible_basic'

The above exception was the direct cause of the following exception:

Traceback (most recent call last):
  File "/home/tristan8/stanford_redcap/venv/lib/python3.10/site-packages/streamlit/runtime/scriptrunner/exec_code.py", line 128, in exec_func_with_error_handling
    result = func()
  File "/home/tristan8/stanford_redcap/venv/lib/python3.10/site-packages/streamlit/runtime/scriptrunner/script_runner.py", line 669, in code_to_exec
    exec(code, module.__dict__)  # noqa: S102
  File "/home/tristan8/stanford_redcap/dashboard/dashboard.py", line 686, in <module>
    main()
  File "/home/tristan8/stanford_redcap/dashboard/dashboard.py", line 665, in main
    metrics = dashboard.calculate_metrics(df)
  File "/home/tristan8/stanford_redcap/dashboard/dashboard.py", line 163, in calculate_metrics
    eligible_df = df[df['is_eligible_basic'] == '1']
  File "/home/tristan8/stanford_redcap/venv/lib/python3.10/site-packages/pandas/core/frame.py", line 4107, in __getitem__
    indexer = self.columns.get_loc(key)
  File "/home/tristan8/stanford_redcap/venv/lib/python3.10/site-packages/pandas/core/indexes/base.py", line 3819, in get_loc
    raise KeyError(key) from err
KeyError: 'is_eligible_basic'

  You can now view your Streamlit app in your browser.

  Local URL: http://localhost:8080
  Network URL: http://171.64.52.112:8080
  External URL: http://171.64.52.112:8080

2025-07-01 13:21:56.519 Uncaught app execution
Traceback (most recent call last):
  File "/home/tristan8/stanford_redcap/venv/lib/python3.10/site-packages/pandas/core/indexes/base.py", line 3812, in get_loc
    return self._engine.get_loc(casted_key)
  File "pandas/_libs/index.pyx", line 167, in pandas._libs.index.IndexEngine.get_loc
  File "pandas/_libs/index.pyx", line 196, in pandas._libs.index.IndexEngine.get_loc
  File "pandas/_libs/hashtable_class_helper.pxi", line 7088, in pandas._libs.hashtable.PyObjectHashTable.get_item
  File "pandas/_libs/hashtable_class_helper.pxi", line 7096, in pandas._libs.hashtable.PyObjectHashTable.get_item
KeyError: False

The above exception was the direct cause of the following exception:

Traceback (most recent call last):
  File "/home/tristan8/stanford_redcap/venv/lib/python3.10/site-packages/streamlit/runtime/scriptrunner/exec_code.py", line 128, in exec_func_with_error_handling
    result = func()
  File "/home/tristan8/stanford_redcap/venv/lib/python3.10/site-packages/streamlit/runtime/scriptrunner/script_runner.py", line 669, in code_to_exec
    exec(code, module.__dict__)  # noqa: S102
  File "/home/tristan8/stanford_redcap/dashboard/dashboard.py", line 686, in <module>
    main()
  File "/home/tristan8/stanford_redcap/dashboard/dashboard.py", line 665, in main
    metrics = dashboard.calculate_metrics(df)
  File "/home/tristan8/stanford_redcap/dashboard/dashboard.py", line 191, in calculate_metrics
    calendly_appointments = len(eligible_df[eligible_df.get('calendly_booked', '0') == '1'])
  File "/home/tristan8/stanford_redcap/venv/lib/python3.10/site-packages/pandas/core/frame.py", line 4107, in __getitem__
    indexer = self.columns.get_loc(key)
  File "/home/tristan8/stanford_redcap/venv/lib/python3.10/site-packages/pandas/core/indexes/base.py", line 3819, in get_loc
    raise KeyError(key) from err
KeyError: False
2025-07-01 19:03:49.035 Uncaught app execution
Traceback (most recent call last):
  File "/home/tristan8/stanford_redcap/venv/lib/python3.10/site-packages/pandas/core/indexes/base.py", line 3812, in get_loc
    return self._engine.get_loc(casted_key)
  File "pandas/_libs/index.pyx", line 167, in pandas._libs.index.IndexEngine.get_loc
  File "pandas/_libs/index.pyx", line 196, in pandas._libs.index.IndexEngine.get_loc
  File "pandas/_libs/hashtable_class_helper.pxi", line 7088, in pandas._libs.hashtable.PyObjectHashTable.get_item
  File "pandas/_libs/hashtable_class_helper.pxi", line 7096, in pandas._libs.hashtable.PyObjectHashTable.get_item
KeyError: 'overall_eligibility'

The above exception was the direct cause of the following exception:

Traceback (most recent call last):
  File "/home/tristan8/stanford_redcap/venv/lib/python3.10/site-packages/streamlit/runtime/scriptrunner/exec_code.py", line 128, in exec_func_with_error_handling
    result = func()
  File "/home/tristan8/stanford_redcap/venv/lib/python3.10/site-packages/streamlit/runtime/scriptrunner/script_runner.py", line 669, in code_to_exec
    exec(code, module.__dict__)  # noqa: S102
  File "/home/tristan8/stanford_redcap/dashboard/dashboard.py", line 686, in <module>
    main()
  File "/home/tristan8/stanford_redcap/dashboard/dashboard.py", line 665, in main
    metrics = dashboard.calculate_metrics(df)
  File "/home/tristan8/stanford_redcap/dashboard/dashboard.py", line 163, in calculate_metrics
    eligible_df = df[df['overall_eligibility'] == '1']
  File "/home/tristan8/stanford_redcap/venv/lib/python3.10/site-packages/pandas/core/frame.py", line 4107, in __getitem__
    indexer = self.columns.get_loc(key)
  File "/home/tristan8/stanford_redcap/venv/lib/python3.10/site-packages/pandas/core/indexes/base.py", line 3819, in get_loc
    raise KeyError(key) from err
KeyError: 'overall_eligibility'
